Workbook

Sheet فهرست
A1: بسمه تعالی
B3: هيأت امناء محترم پارک علم و فناوری خراسان
B4: با احترام
B5: به پيوست صورتهاي مالي پارک علم و فناوری خراسان رضوی و یادداشتهای همراه که بر اساس استانداردهای
B6: حسابداری بخش عمومی تهیه و تنظیم گردیده، برای سال مالی منتهی به 29 اسفندماه 1398 به شرح زير تقديم مي‌گردد :
C7: شـــــــرح | I7: شماره صفحه
C8: صورت وضعیت مالی | I8: 2
C9: صورت تغییرات در وضعیت مالی | I9: 3
C10: صورت مقایسه بودجه و عملکرد | I10: 4
C12: يادداشتهاي توضيحي همراه صورتهای مالی:
D13: الف: تاريخچه فعاليت پارك علم و فناوري | I13: 5
D14: ب: مبناي تهيه صورتهای مالی | I14: 5-8
D15: ج- يادداشتهاي مربوط به اقلام مندرج در صورتهاي مالي | I15: 9-43
B19: صورتهاي مالي در تاريخ 1399/09/09 به تأييد مسئولين پارك رسيده است.
B20: مسئولين امضاء كننده صورتهاي مالي | G20: سمت | I20: امضاء
B22: رضا قنبری | G22: رئیس پارک
B24: اکبر امینی | G24: مدیر امور مالی

Sheet ت
A1: پارک علم و فناوری خراسان
A2: صورت وضعیت مالی
A3: در تاریخ 29 اسفند ماه 1398
F4: (تجدید ارایه شده) | O4: (تجدید ارایه شده)
A5: دارایی‎ها | C5: یادداشت | E5: 1398/12/29 | G5: 1397/12/29 | I5: بدهی‎ها و ارزش خالص | K5: یادداشت | M5: 1398/12/29 | O5: 1397/12/29
E6: ریال | G6: ریال | M6: ریال | O6: ریال
A7: دارایی‎های جاری | I7: بدهی‎های جاری
A8: موجودی نقد | C8: 4 | E8: =يادداشتها!F12 -> 110234473507 | F8: =يادداشتها!G12 -> 0 | G8: =يادداشتها!H12 -> 28201194476 | I8: حساب‎های پرداختنی حاصل از عملیات مبادله‎ای | K8: 12 | M8: =يادداشتها!F226 -> 12057773251 | N8: =يادداشتها!G226 -> 0 | O8: =يادداشتها!H226 -> 6692411625
A9: حساب‎ها و اسناد دریافتنی حاصل از عملیات مبادله‎ای | C9: 5 | E9: =يادداشتها!F72 -> 17602460634 | F9: =يادداشتها!G72 -> 0 | G9: =يادداشتها!H72 -> 11801010994 | I9: حساب‎های پرداختنی حاصل از عملیات غیر مبادله‎ای | K9: 13 | M9: =يادداشتها!F266 -> 0 | N9: =يادداشتها!G266 -> 0 | O9: =يادداشتها!H266 -> 1753349492
A10: حساب‎های دریافتنی حاصل از عملیات غیر مبادله‎ای | C10: 6 | E10: =يادداشتها!F94 -> 10149042108 | F10: =يادداشتها!G94 -> 0 | G10: =يادداشتها!H94 -> 1734077013 | I10: پیش‎دریافت‎ها | K10: 14 | M10: =يادداشتها!F272 -> 0 | N10: =يادداشتها!G272 -> 0 | O10: =يادداشتها!H272 -> 2607500000
A11: پیش‎پرداخت‎ها | C11: 7 | E11: =يادداشتها!F103 -> 1502834359 | F11: =يادداشتها!G103 -> 0 | G11: =يادداشتها!H103 -> 3228122359
A12: جمع دارایی‎های جاری | E12: =SUM(E8:E11) -> 139488810608 | F12: =SUM(F8:F11) -> 0 | G12: =SUM(G8:G11) -> 44964404842 | H12: =يادداشتها!I103 -> 0 | I12: جمع بدهی‎های جاری | M12: =SUM(M8:M11) -> 12057773251 | O12: =SUM(O8:O11) -> 11053261117
A13: دارایی‎های غیرجاری | I13: بدهی‎های غیرجاری
I14: ذخیره مزایای پایان خدمت کارکنان | K14: 15 | M14: =يادداشتها!F283 -> 24569309765 | N14: =يادداشتها!G283 -> 0 | O14: =يادداشتها!H283 -> 21394779005
A15: دارایی‎های ثابت مشهود | C15: 8 | E15: ='دارایی ثابت مشهود'!N16 -> 930623919515 | G15: ='دارایی ثابت مشهود'!O16 -> 906823308496 | I15: سایر بدهی‎های غیرجاری | K15: 16 | M15: =يادداشتها!F292 -> 2489711811 | N15: =يادداشتها!G292 -> 0 | O15: =يادداشتها!H292 -> 2054176320
A16: دارایی‎های نامشهود | C16: 9 | E16: ='دارایی نامشهود'!N11 -> 32387008784 | F16: =يادداشتها!G192 -> 0 | G16: ='دارایی نامشهود'!O11 -> 28344320833 | I16: جمع بدهی‎های غیرجاری | M16: =SUM(M14:M15) -> 27059021576 | O16: =SUM(O14:O15) -> 23448955325
A17: سرمایه گذاری‎های بلند مدت | C17: 10 | E17: =يادداشتها!F200 -> 25301169258 | F17: =يادداشتها!G200 -> 0 | G17: =يادداشتها!H200 -> 18362300000 | I17: جمع بدهی ها | M17: =M16+M12 -> 39116794827 | O17: =O16+O12 -> 34502216442
A18: سایر دارایی ها | C18: 11 | E18: =يادداشتها!F209 -> 36673485202 | F18: =يادداشتها!G209 -> 0 | G18: =يادداشتها!H209 -> 28682034677 | H18: =يادداشتها!I209 -> 0 | I18: ارزش خالص
I19: ارزش خالص انباشته | M19: =ع!G31 -> 1125357598540 | O19: =ع!I31 -> 9.9267415e+11
A20: جمع دارایی‎های غیرجاری | E20: =SUM(E15:E19) -> 1024985582759 | G20: =SUM(G15:G19) -> 982211964006 | I20: جمع ارزش خالص | M20: =SUM(M19:M19) -> 1125357598540 | O20: =SUM(O19:O19) -> 9.9267415e+11
A21: جمع دارایی‎ها | E21: =E20+E12 -> 1164474393367 | G21: =G20+G12 -> 1027176368848 | I21: جمع بدهی‎ها و ارزش خالص | M21: =M20+M17 -> 1164474393367 | O21: =O20+O17 -> 1.0271764e+12
A23: یادداشت‎های توضیحی، بخش جدایی‎ناپذیر صورت‎های مالی است.
A24: مدير امورمالی | H24: رئیس پارك
A25: اکبر امینی | I25: رضا قنبری
A26: 2
I27: =M21-E21 -> 0
I28: =G21-O21 -> 0.140625

Sheet ع
A1: پارک علم و فناوری خراسان
A2: صورت تغییرات در وضعیت مالی
A3: برای سال مالي منتهي به 29 اسفند ماه 1398
I4: (تجدید ارایه شده)
C5: یادداشت | E5: 1398/12/29 | I5: 1397/12/29
E6: ریال | G6: ریال | I6: ریال
A7: درآمدها
A8: دریافتی از خزانه از محل اعتبارات تخصیص یافته | C8: 17 | E8: =يادداشتها!F301 -> 175005286000 | I8: =يادداشتها!H301 -> 91649531188
A9: دریافتی از خزانه از محل درآمدهای اختصاصی | C9: 18 | E9: =يادداشتها!F328 -> 54519819997 | I9: =يادداشتها!H328 -> 4.376349e+10
A10: سایر درآمدها | C10: 19 | E10: =يادداشتها!F336 -> 30660000000 | I10: =يادداشتها!H336 -> 0
A11: جمع | G11: =SUM(E8:E10) -> 260185105997 | I11: =SUM(I8:I10) -> 1.3541302e+11
A12: هزینه‎ها
A13: جبران خدمت کارکنان | C13: 20 | E13: =-يادداشتها!F340 -> -41166368694 | I13: =-يادداشتها!H340 -> -34630767018
A14: استفاده از کالاها و خدمات | C14: 21 | E14: =-يادداشتها!F341 -> -63953679667 | I14: =-يادداشتها!H341 -> -51222040682
A15: رفاه اجتماعي | C15: 22 | E15: =-يادداشتها!F342 -> -3334194640 | I15: =-يادداشتها!H342 -> -2885370336
A16: ساير هزينه‌ها | C16: 23 | E16: =-يادداشتها!F343 -> -32147845169 | I16: =-يادداشتها!H343 -> -10318906211
A17: هزینه استهلاک | C17: 24 | E17: =-يادداشتها!F402 -> -9425648135 | I17: =-يادداشتها!H402 -> -9109233883
A18: جمع | G18: =SUM(E13:E17) -> -150027736305 | I18: =SUM(I13:I17) -> -108166318130
A20: درآمد های دولت | C20: 25 | E20: =يادداشتها!F416 -> 78732076442 | I20: =يادداشتها!H416 -> 40344161074
A21: کسر میشود وجوه ارسالی به خزانه | C21: 26 | E21: =-'درآمد دولت'!C5 -> -56206000000 | I21: -45117000000
A22: جمع | G22: =SUM(E20:E21) -> 22526076442 | I22: =SUM(I20:I21) -> -4772838926
A23: خالص تغییر در وضعیت مالی | G23: =G11+G18+G22 -> 132683446134 | I23: =I11+I18+I22 -> 2.2473864e+10
A25: گردش حساب تغییرات در ارزش خالص
A26: ارزش خالص انباشته ابتدای سال | E26: =996533198504 -> 996533198504 | I26: =69261363155-6267448227 -> 62993914928
A27: تعديلات سنواتي | C27: 28 | E27: =يادداشتها!F438 -> -3859046098 | I27: =-127512857600%+1052501129 -> -222627447
A28: ارزش خالص انباشته ابتدای سال تعدیل شده | G28: =SUM(E26:E27) -> 992674152406 | I28: =SUM(I26:I27) -> 62771287481
A29: شناسایی اولیه دارایی ها | G29: 0 | I29: =906073099794+1355901000 -> 907429000794
A30: خالص تغییر در وضعیت مالی | G30: =G23 -> 132683446134 | I30: =I23 -> 2.2473864e+10
A31: ارزش خالص انباشته پایان سال | D31: 39953216994 | G31: =SUM(G28:G30) -> 1125357598540 | I31: =I28+I30+I29 -> 9.9267415e+11
A33: یادداشت‎های توضیحی، بخش جدایی‎ناپذیر صورت‎های مالی است.
A34: مدير امورمالی | H34: رئیس پارك
A35: اکبر امینی | G35: رضا قنبری
A36: 3

Sheet تفریغ
A1: پارک علم و فناوری خراسان
A2: صورت مقایسه بودجه و عملکرد
A3: برای سال مالی منتهی 29 اسفند ماه 1398
D5: بودجه | H5: عملکرد بر مبنای | J5: تفاوت بودجه
B6: یادداشت | D6: اولیه | F6: نهایی | H6: قابل مقایسه | J6: نهایی و عملکرد
D7: ریال | F7: ریال | H7: ریال | J7: ریال
A8: منابع | B8: 27-1
A9: دریافتی از محل اعتبارات هزینه عمومی | D9: =' مصوب'!E6+'وجوه مصرف نشده'!H7+'وجوه مصرف نشده'!H9+'سايرمنابع جاری'!D18 -> 165155772833 | F9: =' مصوب'!E6+'وجوه مصرف نشده'!H7+'وجوه مصرف نشده'!H9+'سايرمنابع جاری'!D18+ابلاغي!E6+'سايرمنابع جاری'!E18 -> 236130058833 | H9: =' مصوب'!F6+'وجوه مصرف نشده'!H7+'وجوه مصرف نشده'!H9+ابلاغي!E6+'سايرمنابع جاری'!G18 -> 206851058833 | J9: =H9-F9 -> -29279000000 | L9: =' مصوب'!E6-' مصوب'!F6 -> 29279000000
A10: دریافتی از محل اعتبارات هزینه اختصاصی | D10: =' مصوب'!C10+'وجوه مصرف نشده'!C17 -> 4.3490149e+10 | F10: =' مصوب'!E10+'وجوه مصرف نشده'!C17 -> 6.0896149e+10 | H10: =' مصوب'!J10+'وجوه مصرف نشده'!H17 -> 5.0909969e+10 | J10: =H10-F10 -> -9986180003 | L10: =' مصوب'!E10-' مصوب'!F10 -> 1686180000
A11: دریافتی از محل اعتبارات تملک دارایی های سرمایه ای | D11: =' مصوب'!C14+'وجوه مصرف نشده'!H19+'وجوه مصرف نشده'!H24 -> 33071116623 | F11: =' مصوب'!E14+'وجوه مصرف نشده'!H19+'وجوه مصرف نشده'!H24+ابلاغي!C15 -> 45671116623 | H11: =' مصوب'!J14+'وجوه مصرف نشده'!H19+'وجوه مصرف نشده'!H24+ابلاغي!C15 -> 43321116623 | J11: =H11-F11 -> -2350000000 | L11: =' مصوب'!E14-' مصوب'!F14 -> 10650000000
A12: جمع منابع | D12: =SUM(D9:D11) -> 2.4171704e+11 | F12: =SUM(F9:F11) -> 3.4269732e+11 | H12: =SUM(H9:H11) -> 3.0108214e+11 | J12: =SUM(J9:J11) -> -41615180003 | K12: عدم تخصیص | L12: =' مصوب'!E20-' مصوب'!F20+J12 -> -3
A14: مصارف | B14: 27-2
A15: هزینه های عمومی | D15: =D9 -> 165155772833 | F15: =F9 -> 236130058833 | H15: =' مصوب'!Q6+'وجوه مصرف نشده'!M7+'وجوه مصرف نشده'!M9+ابلاغي!J6+'سايرمنابع جاری'!K18 -> 121872419199 | J15: =F15-H15 -> 114257639634 | L15: =ROUND(J15+J9-يادداشتها!F7,0) -> 0
A16: هزینه های اختصاصی | D16: =D10 -> 4.3490149e+10 | F16: =F10 -> 6.0896149e+10 | H16: =' مصوب'!Q10+'وجوه مصرف نشده'!M17 -> 37093587201 | J16: =F16-H16 -> 2.3802562e+10 | L16: =J16+J10-يادداشتها!F8 -> 0.040000916
A17: تملک دارایی های سرمایه ای | D17: =D11 -> 33071116623 | F17: =F11 -> 45671116623 | H17: =' مصوب'!Q14+'وجوه مصرف نشده'!M19+'وجوه مصرف نشده'!M24+ابلاغي!J15 -> 27871116623 | J17: =F17-H17 -> 17800000000 | L17: =J17+J11-يادداشتها!F9 -> 15100000000
A18: جمع مصارف | D18: =SUM(D15:D17) -> 2.4171704e+11 | F18: =SUM(F15:F17) -> 3.4269732e+11 | H18: =SUM(H15:H17) -> 186837123023 | J18: =SUM(J15:J17) -> 1.558602e+11
A19: مازاد وجوه مصرف نشده | D19: =D18-D12 -> 0 | F19: =F18-F12 -> 0 | H19: =H12-H18 -> 1.1424502e+11 | J19: =J18+J12 -> 1.1424502e+11 | L19: =J19-يادداشتها!F7-يادداشتها!F8-يادداشتها!F9 -> 1.51e+10
A21: مبلغ 114.245 میلیون ریال شامل مبلغ 99.145 میلیون ریال وجه نقد و مبلغ 15.100 میلیون ریال اسناد خزانه اسلامی می باشد
A22: یادداشت‎های توضیحی، بخش جدایی‎ناپذیر صورت‎های مالی است
A23: مدیر امور مالی | G23: رئیس پارک
A24: اکبر امینی | H24: رضا قنبری
B25: 4
L34: 1353589

Sheet منابع ومصارف
A1: پارک علم و فناوری خراسان
A2: يادداشتهاي توضيحي صورتهای مالی
A3: سال مالي منتهي به 29 اسفند ماه 1398
A5: -27 | B5: منابع و مصارف صورت مقایسه بودجه با عملکرد سال مالی 1398 به شرح زیر قابل تفکیک می باشد:
A6: -27-1 | B6: منابع صورت مقایسه بودجه با عملکرد سال مالی 1398 :
E7: بودجه نهایی | G7: عملکرد بر مبنای قابل مقایسه | I7: تفاوت بودجه نهایی و عملکرد
B9: منابع | E9: ریال | G9: ریال | I9: ریال
B10: اعتبارات مصوب هزینه ای | E10: =تفریغ!F9-E13 -> 195815772833 | G10: =تفریغ!H9-'منابع ومصارف'!G13 -> 166536772833 | I10: =G10-E10 -> -29279000000 | K10: =E10-تفریغ!F9+E13 -> 0
B11: اعتبارات تملک دارایی های سرمایه ای | E11: =تفریغ!F11 -> 45671116623 | G11: =تفریغ!H11 -> 43321116623 | I11: =G11-E11 -> -2350000000
B12: درآمدهای اختصاصی | E12: =تفریغ!F10 -> 6.0896149e+10 | G12: =تفریغ!H10 -> 5.0909969e+10 | I12: =G12-E12 -> -9986180003 | K12: =E12-تفریغ!F10 -> 0
B13: اعتبارات ابلاغی هزینه ای | E13: =ابلاغي!C6 -> 40314286000 | G13: =E13 -> 40314286000 | I13: =G13-E13 -> 0
B14: جمع منابع | E14: =SUM(E10:E13) -> 3.4269732e+11 | G14: =SUM(G10:G13) -> 3.0108214e+11 | I14: =SUM(I10:I13) -> -41615180003 | K14: =E14-تفریغ!F12 -> 0 | L14: =G14-تفریغ!H12 -> 0
A16: -27-2 | B16: مصارف صورت مقایسه بودجه با عملکرد سال مالی 1398 :
E17: بودجه نهایی | G17: عملکرد بر مبنای قابل مقایسه | I17: تفاوت بودجه نهایی و عملکرد
B18: مصارف
A19: الف - هزینه های پرسنلی:
B20: حقوق و مزایای پرسنل اعضای هیات علمی (حق مدیریت) | E20: 1800000000 | G20: =يادداشتها!F349 -> 564000000 | I20: =E20-G20 -> 1236000000
B21: حقوق و مزایای پرسنل اعضای غیر هیات علمی(رسمی-پیمانی-قراردادی):
B22: حقوق ومزایای مستمر | E22: 25000000000 | G22: =يادداشتها!F351 -> 24515569973 | I22: =E22-G22 -> 484430027
B23: عیدی و پاداش و اضافه کاری | E23: 2500000000 | G23: =يادداشتها!F352 -> 2292736520 | I23: =E23-G23 -> 207263480
B24: بازخرید مرخصي و سنوات | E24: 11000000000 | G24: =يادداشتها!F353 -> 9154706902 | I24: =E24-G24 -> 1845293098
B25: بيمه سهم کارفرما رسمي و پيماني | E25: 5000000000 | G25: =يادداشتها!F354 -> 4630782797 | I25: =E25-G25 -> 369217203
B26: ساير | E26: 3500000000 | G26: =يادداشتها!F355 -> 8572502 | I26: =E26-G26 -> 3491427498
A27: ب - سایر هزینه ها
B28: مواد و لوازم مصرف شدنی | E28: 3500000000 | G28: =يادداشتها!F360 -> 1386530895 | I28: =E28-G28 -> 2113469105
B29: حق ماموريت | E29: 3000000000 | G29: =يادداشتها!F361 -> 1704573048 | I29: =E29-G29 -> 1295426952
B30: مواد آزمایشگاهی | E30: 3500000000 | G30: =يادداشتها!F362 -> 774758417 | I30: =E30-G30 -> 2725241583
B31: حق ارزيابي و کارشناسي و داوری | E31: 6000000000 | G31: =يادداشتها!F363 -> 1964594524 | I31: =E31-G31 -> 4035405476
B32: خدمات نگهبانی | E32: 10000000000 | G32: =يادداشتها!F364 -> 7820828061 | I32: =E32-G32 -> 2179171939
B33: خدمات نظافت | E33: 8500000000 | G33: =يادداشتها!F365 -> 6838659807 | I33: =E33-G33 -> 1661340193
B34: خدمات فضای سبز | E34: 4200000000 | G34: =يادداشتها!F366 -> 2524881752 | I34: =E34-G34 -> 1675118248
B35: خدمات پشتیبانی فناوری | E35: 13000000000 | G35: =يادداشتها!F367 -> 6467000000 | I35: =E35-G35 -> 6533000000
B36: خدمات حمل و نقل | E36: 4000000000 | G36: =يادداشتها!F368 -> 2888538474 | I36: =E36-G36 -> 1111461526
B37: خدمات شبکه و فناوری اطلاعات | E37: 4000000000 | G37: =يادداشتها!F369 -> 3875018939 | I37: =E37-G37 -> 124981061
B38: هزينه چاپ،صفحه آرايي ،نشريات و تبلیغات | E38: 1200000000 | G38: =يادداشتها!F370 -> 575195729 | I38: =E38-G38 -> 624804271
B39: تعمير و نگهداري ساختمان و مستحدثات | E39: 19000000000 | G39: =يادداشتها!F371 -> 8207818092 | I39: =E39-G39 -> 10792181908
... B44: آب و برق و سوخت و تلفن و پست | E44: 15000000000 | G44: =يادداشتها!F376 -> 4863112730 | I44: =E44-G44 -> 10136887270
B45: نمايشگاه داخلي و خارجی | E45: 3500000000 | G45: =يادداشتها!F390 -> 1290348400 | I45: =E45-G45 -> 2209651600
B46: =يادداشتها!B392 -> قرارداد های پژوهشی سه جانبه | E46: =56000000000-5019000000 -> 50981000000 | G46: =يادداشتها!F392 -> 26633777678 | I46: =E46-G46 -> 24347222322
B47: حمایت مالی مستقیم از واحد های فناور | E47: =52000000000+5019000000 -> 57019000000 | G47: =' مصوب'!L20+2549000000 -> 14255881683 | I47: =E47-G47 -> 42763118317
...

Sheet حمایت ها
A1: پارک علم و فناوری خراسان
A2: يادداشتهاي توضيحي صورتهای مالی
A3: سال مالي منتهي به 29 اسفند ماه 1398
A4: 27-3 | B4: حمایت مالی مستقیم از واحدهای فناور در اصلاحیه بودجه تفصیلی سال 1398 به مبلغ 019ر57 میلیون ریال در نظر گرفته شده است که از مبلغ مزبور مبلغ 255ر14 میلیون ریال معادل 25% به واحدهای فناور به شرح زیر پرداخت گردیده است .
D6: یادداشت | E6: 1398
E7: ريال
B8: حمایت مالی از واحدهای دوره پیش رشد | D8: 27-3-1 | E8: =E44 -> 2272649000
B9: حمایت مالی از واحدهای دوره رشد | D9: 27-3-2 | E9: =E84 -> 9483100000
B10: حمایت مالی از واحدهای فناور | D10: 27-3-3 | E10: =E89 -> 2500000000
B11: جمع | E11: =SUM(E8:E10) -> 14255749000
E13: 1398
A14: 27-3-1 | B14: حمایت مالی از واحدهای دوره پیش رشد به شرح ذیل می باشد: | E14: ريال
C15: سعيد معصوم زاده | D15: حمايتي پيش رشد | E15: 75000000
C16: مهدي سليماني | D16: حمايتي پيش رشد | E16: 47500000
C17: فاطمه عباس زاده | D17: حمايتي پيش رشد | E17: 55000000
C18: محمد جواد منفرد | D18: حمايتي پيش رشد | E18: 107649000
C19: صدراله خاكسار ديسفاني | D19: حمايتي پيش رشد | E19: 55000000
C20: مرتضي آذر نوشان | D20: حمايتي پيش رشد | E20: 102500000
C21: علي اصغري | D21: حمايتي پيش رشد | E21: 47500000
C22: محمد باقر صابري مقدم طهراني | D22: حمايتي پيش رشد | E22: 125000000
C23: جواد غلامي شيراز | D23: حمايتي پيش رشد | E23: 102500000
C24: حسين پاكدل نوقابي | D24: حمايتي پيش رشد | E24: 125000000
C25: اميد مقدس | D25: حمايتي پيش رشد | E25: 72500000
C26: احسان عظيمي راد | D26: حمايتي پيش رشد | E26: 100000000
... C43: نسیم سلطانخواه | D43: حمايتي پيش رشد | E43: 50000000
C44: جمع | E44: =SUM(E15:E43) -> 2272649000
A46: 27-3-2 | B46: حمایت مالی از واحدهای دوره رشد به شرح ذیل می باشد: | E46: 1398
E47: ریال
C48: آرون زيست طب پاز | D48: دوره رشد | E48: 310000000
C49: آريا تكين هنر نوانديش | D49: دوره رشد | E49: 398000000
C50: آريا صنعت هوشمند اسپاد | D50: دوره رشد | E50: 60000000
C51: ابر صنعت اكسون شرق | D51: دوره رشد | E51: 560000000
C52: ارغوان توس مشرق زمين | D52: دوره رشد | E52: 760000000
C53: افزودني هاي طبيعي گلچين توس | D53: دوره رشد | E53: 60000000
C54: امين فاطمي محمدآباد-غزل گوهر دردانه درخشان | D54: دوره رشد | E54: 584000000
C55: باهشت گردشگر ايرانيان | D55: دوره رشد | E55: 584000000
C56: بهسامان انرژي روژان توس | D56: دوره رشد | E56: 56000000
C57: تابان انديش برجيس | D57: دوره رشد | E57: 120000000
C58: تجهيز بتن مهدي | D58: دوره رشد | E58: 60000000
C59: تجهيزات پيشرفته درمان توس شركت | D59: دوره رشد | E59: 120000000
...

Sheet تعدیلات
B2: شرح | C2: شماره یادداشت | D2: مانده قبل از تعدیلات | E2: تعدیلات | G2: مانده پس از تعدیلات
E3: بدهکار | F3: بستانکار
D4: ریال | E4: ریال | F4: ریال | G4: ریال
B5: حسابها و اسناد دریافتنی حاصل از عملیات مبادله ای | C5: 5 | D5: =يادداشتها!H72+6267448227 -> 18068459221 | E5: 0 | F5: 6267448227 | G5: =D5+E5-F5 -> 11801010994
B6: ارزش خالص اول دوره | C6: - | D6: =996533198504 -> 996533198504 | E6: =F5 -> 6267448227 | F6: =E7+E8 -> 2408402129 | G6: =D6+F6-E6 -> 992674152406
B7: دارایی‎های ثابت مشهود | C7: 8 | D7: ='دارایی ثابت مشهود'!E16-1355901000 -> 922188388979 | E7: 1355901000 | F7: 0 | G7: =D7+E7-F7 -> 923544289979
B8: سایر دارایی ها | C8: 9 | D8: =يادداشتها!H209-1052501129 -> 27629533548 | E8: 1052501129 | F8: 0 | G8: =D8+E8-F8 -> 28682034677
B9: جمع | D9: =SUM(D5:D8) -> 1964419580252 | E9: =SUM(E5:E8) -> 8675850356 | F9: =SUM(F5:F8) -> 8675850356 | G9: =SUM(G5:G8) -> 1956701488056

Sheet يادداشتها
A1: پارک علم و فناوری خراسان
A2: يادداشتهاي توضيحي صورتهای مالی
A3: سال مالي منتهي به 29 اسفند ماه 1398
A4: -4 | B4: مانده حساب موجودي نزد بانکها به شرح زير قابل تفکیک مي‌باشد:
D5: يادداشت | F5: 1398 | H5: 1397
F6: ریال | H6: ریال
B7: موجودی نزد بانکهای حساب مستقل اعتبارات هزینه ای | D7: 4-1 | F7: =F29 -> 84978639634 | H7: =H29 -> 19191012833 | I7: =I29 -> 0 | J7: =F7+F8+F9-' مصوب'!R20-'وجوه مصرف نشده'!S28-ابلاغي!K19-'سايرمنابع جاری'!L18 -> -0.040000916
B8: موجودی نزد بانکهای حساب مستقل اعتبارات اختصاصي | D8: 4-2 | F8: =F35 -> 13816381843 | H8: =H35 -> 4690149047 | I8: =I35 -> 0
B9: موجودی نزد بانکهای حساب مستقل تملک دارائیهای سرمایه ای | D9: 4-3 | F9: =F42 -> 350000000 | H9: =H42 -> 1451116623 | I9: =I41 -> 0
B10: موجودی نزد بانکهای حساب مستقل سپرده | D10: 4-5 | F10: =F49 -> 8673783102 | H10: =H49 -> 2157694452 | J10: =F10-F244 -> 0
B11: موجودی نزد بانکها آخر سال قابل واریز به حساب غیر قابل برداشت | D11: 4-6 | F11: =F65 -> 2415668928 | H11: =H65 -> 711221521
F12: =SUM(F7:F11) -> 110234473507 | H12: =SUM(H7:H11) -> 28201194476 | J12: =F12-110234473507 -> 0
A14: -4-1 | B14: موجودی نزد بانک حساب مستقل اعتبارات هزینه ای به شرح زیر قابل تفکیک می باشد: | F14: 1398 | H14: 1397
F15: ریال | H15: ریال
B16: بانک تجارت حساب 425080008 | F16: =32716328009+6057450800 -> 38773778809 | H16: 16012888341
B17: بانک تجارت حساب 425080806 | F17: =2189475000+1811902759 -> 4001377759 | H17: 29839759
B18: بانک سپه حساب 5152051601006 | F18: 0 | H18: 436536
B19: بانک تجارت حساب 425112554 | F19: =4545385298+1096858196 -> 5642243494 | H19: 96858196
B20: بانک تجارت حساب 425066668 | F20: 0 | H20: 1
B21: بانک تجارت حساب 425060880 | F21: 0 | H21: 990000
B22: پشتيبان حسابدومنظوره 425303996 | F22: 104631737 | H22: 0
B23: بانک تجارت حساب 425080792 | F23: 102379975 | H23: 0
B24: بانک قرض الحسنه مهر ایران | F24: 0 | H24: 1000000000
B25: حساب سپرده حمايتي صندوق پژوهش | D25: 4-1-1 | F25: 2868213550 | H25: 0
B26: حساب رسالت 1000227120077001 | F26: =850000000+1000000000 -> 1850000000 | H26: 2050000000
B27: حساب رسالت 1071200772 | F27: 14136014310 | H27: 0
B28: 4101104900191933اعتبارات عمومي | F28: =2500478000+15000000000-478000 -> 17500000000 | H28: 0
B29: جمع کل | F29: =SUM(F16:F28) -> 84978639634 | H29: =SUM(H16:H28) -> 19191012833 | I29: =SUM(I16:I28) -> 0
A31: -4-1-1 | B31: مانده حساب سپرده حمایتی صندوق پژوهش مربوط به مانده وجوه نزد صندوق پژوهش و فناوری استان خراسان رضوی می باشد که طبق قرارداد عاملیت فیمابین جهت پرداخت بسته های حمایتی به واحد های فناور پارک از آن استفاده می شود.
A32: -4-2 | B32: موجودی نزد بانکهای حساب مستقل درآمدهای اختصاصی به شرح زیر قابل تفکیک می باشد : | F32: 1398 | H32: 1397
F33: ریال | H33: ریال
B34: بانک تجارت حساب 425080814 | F34: 13816381843 | H34: 4690149047
B35: جمع کل | F35: =SUM(F34:F34) -> 13816381843 | H35: =SUM(H34:H34) -> 4690149047
A37: -4-3 | B37: موجودی نزد بانکهای حساب مستقل تملک دارائیهای سرمایه ای به شرح زیر قابل تفکیک می باشد : | F37: 1398 | H37: 1397
F38: ریال | H38: ریال
B39: بانک تجارت حساب 425112554 | F39: 2359753 | H39: 1168141804
B40: بانک تجارت حساب 425303996 | F40: 0 | H40: 242067863
B41: بانک تجارت حساب 425080792 | F41: 347640247 | H41: 40906956
F42: =SUM(F39:F41) -> 350000000 | H42: =SUM(H39:H41) -> 1451116623
A44: -4-5 | B44: موجودی نزد بانکهای حساب سپرده به شرح زیر قابل تفکیک می باشد : | F44: 1398 | H44: 1397
...

Sheet یادداشتها2
A1: -28 | B1: تعدیلات طی دوره به شرح زیر قابل تفکیک می باشد
D2: 1398 | F2: 1397
D3: ریال | F3: ریال
B4: اصلاح مانده اسناد دریافتنی اول دوره | D4: -6267448227 | F4: =-1275128576 -> -1275128576
B5: اصلاح دارایی های ثابت اول دوره | D5: 1355901000 | F5: 0
B6: اصلاح سایر دارایی ها اول دوره | D6: 1052501129 | F6: 0
B7: جمع | D7: =SUM(D4:D6) -> -3859046098 | F7: =SUM(F4:F6) -> -1275128576
A18: د: گروه حسابهای انتظامی
A19: -29 | B19: مانده حساب انتظامی به شرح زیر قابل تفکیک می باشد: | C19: صفحه | D19: 1398 | F19: 1397
D20: ریال | F20: ریال
B21: تضمينات حساب مستقل جاری-اسناد انتظامی دیگران نزد ما | D21: =87410691669+17325548970 -> 104736240639 | F21: 87410691669
B22: تضمینات حساب مستقل عمرانی | D22: =40679648435+42235458877 -> 82915107312 | F22: 40679648435
B23: تضمینات حساب مستقل اختصاصی | D23: =11340112930+9946405790 -> 21286518720 | F23: 11340112930 | H23: =H21-H22 -> 0
B24: حسابهای انتظامی - علی الحساب | C24: 14-16 | D24: 1073603123 | F24: 1256412485
B25: حساب انتظامی - کنترل حمایت های مالی از واحد های فناوری | D25: 8784251000 | F25: 0
B26: حسابهای انتظامی - اسناد خزانه اسلامی | D26: 15100000000 | F26: 12030000000
D27: =SUM(D21:D26) -> 233895720794 | F27: =SUM(F21:F26) -> 152716865519
A29: -30 | B29: تعهدات و بدهیهای احتمالی
B30: پارک بابت عوارض بناهای احداث شده، طبق توافقات شفاهی بعمل آمده با شهرداری،حدودا مبلغ 22 میلیارد ریال بدهکار می باشد
B31: که به دلیل عدم قطعیت مورد مزبور، هیچگونه پرداختی صورت نگرفته است.
A33: -31 | B33: وقایع بعد از تاریخ صورت وضعیت مالی
B34: رویداد با اهمیتی که در دوره بعد از تاریخ صورت وضعیت مالی اتفاق افتاده و مستـلزم تعدیل حسابـها و افشای آن در یادداشت های
B35: توضیحی حسابهای مستقل باشد به وقوع نپیوسته است .

Sheet وضعيت پردا غ ق
A1: صورتحساب وضعیت پرداختهای غیر قطعی سنوات قبل اعتبارات (هزینه ای، اختصاصی و تملک داراییهای سرمایه ای) سال 1398
A2: عنوان دستگاه : پارك علم و فناوري خراسان
A3: عنوان | C3: مانده پرداختهای غیر قطعی سنوات قبل دراول سال | E3: هزینه ازمحل پرداختهای غیر قطعی سنوات قبل | G3: واریزنقدی ازمحل پرداختهای غیر قطعی سنوات قبل | I3: جمع هزينه و واريزي | K3: غير قطعي انتقالي به سال بعد
C4: پیش پرداخت | D4: علی الحساب | E4: پیش پرداخت | F4: علی الحساب | G4: پیش پرداخت | H4: علی الحساب | I4: پیش پرداخت | J4: علی الحساب | K4: پیش پرداخت | L4: علی الحساب
A5: جمع عملکرد پرداختهای غیر قطعی سنواتی اعتبارات مصوب هزینه ای | C5: =94000000+42500000+22500000 -> 159000000 | D5: =66811668+145500000 -> 212311668 | E5: =94000000+62500000 -> 156500000 | F5: =32598567+91554010-9554010 -> 114598567 | G5: 0 | H5: 0 | I5: =E5+G5 -> 156500000 | J5: =F5+H5 -> 114598567 | K5: =C5-I5 -> 2500000 | L5: =D5-J5 -> 97713101
A6: جمع عملکرد پرداختهای غیر قطعی سنواتی اعتبارات ابلاغي هزينه اي | C6: 93000000 | D6: =49383970+15176900 -> 64560870 | E6: 93000000 | F6: =39829960+15176900+9554010 -> 64560870 | G6: 0 | H6: 0 | I6: =E6+G6 -> 93000000 | J6: =F6+H6 -> 64560870 | K6: =C6-I6 -> 0 | L6: =D6-J6 -> 0
A7: جمع عملکرد پرداختهای غیر قطعی سنواتی اعتبارات مصوب اختصاصی | C7: =420102535+25000000 -> 445102535 | D7: =475000336+347162784 -> 822163120 | E7: =10000000+15000000 -> 25000000 | F7: =295587256+257532271-13841487 -> 539278040 | G7: 0 | H7: 0 | I7: =E7+G7 -> 25000000 | J7: =F7+H7 -> 539278040 | K7: =C7-I7 -> 420102535 | L7: =D7-J7 -> 282885080
A8: جمع عملکرد پرداختهای غیر قطعی سنواتی اعتبارات مصوب و ابلاغی تملک داراییها | C8: 0 | D8: 100481963 | E8: 0 | G8: 0 | H8: 0 | I8: =E8+G8 -> 0 | J8: =F8+H8 -> 0 | K8: =C8-I8 -> 0 | L8: =D8-J8 -> 100481963
A9: جمع عملکرد پرداختهای غیر قطعی سنواتی سایر منابع هزینه ای | C9: 2531019824 | D9: 49739928 | E9: 2350388000 | F9: =49739928 -> 49739928 | G9: 0 | H9: 0 | I9: =E9+G9 -> 2350388000 | J9: =F9+H9 -> 49739928 | K9: =C9-I9 -> 180631824 | L9: =D9-J9 -> 0
A10: جمع عملکرد پرداختهای غیر قطعی سنواتی سایر منابع عمرانی | C10: 0 | D10: 7154936 | E10: 0 | G10: 0 | H10: 0 | I10: =E10+G10 -> 0 | J10: =F10+H10 -> 0 | K10: =C10-I10 -> 0 | L10: =D10-J10 -> 7154936
A11: جمع كل | C11: =SUM(C5:C10) -> 3228122359 | D11: =SUM(D5:D10) -> 1256412485 | E11: =SUM(E5:E10) -> 2624888000 | F11: =SUM(F5:F10) -> 768177405 | G11: =SUM(G5:G10) -> 0 | H11: =SUM(H5:H10) -> 0 | I11: =SUM(I5:I10) -> 2624888000 | J11: =SUM(J5:J10) -> 768177405 | ... L11: =SUM(L5:L10) -> 488235080
D13: 13
C14: =3228122359 -> 3228122359 | D14: =1256412485 -> 1256412485 | K14: ='مانده پرداختهای غیر قطعی سن'!E41 -> 603234359 | L14: ='مانده پرداختهای غیر قطعی سن'!F41 -> 488235080
B15: سپرداه و ودایع | C15: =C11-C14 -> 0 | D15: =D11-D14 -> 0 | K15: =K11-K14 -> 0 | L15: =L11-L14 -> 0

Sheet ن7
D28: 14
B29: وضعیت پرداختهای غیر قطعی سنوات قبل
A30: مانده از سنوات قبل | B30: =(('وضعيت پردا غ ق'!C11+'وضعيت پردا غ ق'!D11)/1000000) -> 4484.5348
A31: تسویه شده در سال 1398 | B31: =('وضعيت پردا غ ق'!I11+'وضعيت پردا غ ق'!J11)/1000000 -> 3393.0654
A32: مانده در پایان 1398 | B32: =('وضعيت پردا غ ق'!K11+'وضعيت پردا غ ق'!L11)/1000000 -> 1091.4694

Sheet مانده پرداختهای غیر قطعی سن
A1: فهرست مانده پرداختهای غیرقطعی سنواتی اعتبارات (هزینه ای، اختصاصی، تملک دارائیهای سرمایه ای و سایرمنابع) سال مالی منتهی به 29 اسفندماه 1398
A2: پارک علم و فناوری خراسان
A3: نام گیرنده | B3: موضوع پرداخت | C3: سال پرداخت | D3: منبع اعتبار هزینه ای، اختصاصی، تملک دارائیهای سرمایه ای | E3: نوع و مبلغ پرداختی
E4: پیش پرداخت | F4: علی الحساب
A5: رضا قاليباف باغسياه | B5: برنامه تجاري سازي يافته هاي پژوهشي | C5: 1397 | D5: هزينه اي-مصوب ملي | E5: 2500000
A6: اعتبارات هزینه ای پیش پرداخت سنواتی مصوب | E6: =SUM(E5:E5) -> 2500000 | F6: =SUM(F5:F5) -> 0
A7: عليرضا نوريان | B7: توسعه كارآفريني10515 | C7: 1392 | D7: هزينه اي-مصوب ملي | F7: 3000000
A8: علیرضا نوریان | B8: پژوهش و راهبری فناوری | C8: 1396 | D8: هزینه ای مصوب | F8: 14850000
A9: عليرضا نوريان | B9: توسعه كارآفريني10515 | C9: 1391 | D9: هزینه ای مصوب | F9: 5518037
A10: سعيد جسمي | B10: توسعه كارآفريني10515 | C10: 1389 | D10: هزينه اي-مصوب ملي | F10: 1845064
A11: شرکت مهندسي دانش ابزار پيشتاز | B11: توسعه كارآفريني10515 | C11: 1390 | D11: هزينه اي-مصوب ملي | F11: 9000000
A12: ناظمين توس | B12: برنامه تجاري سازي يافته هاي پژوهشي | C12: 1397 | D12: هزينه اي-مصوب ملي | F12: 13500000
A13: مجيد شريعت | B13: برنامه تجاري سازي يافته هاي پژوهشي | C13: 1397 | D13: هزينه اي-مصوب ملي | F13: 50000000
A14: اعتبارات هزینه ای علی الحساب سنواتی مصوب | F14: =SUM(F7:F13) -> 97713101
A15: دکتر سعيد رضا زارع | B15: طرح | C15: 1387 | D15: سايرمنابع | E15: 180631824
A16: اعتبارات سایر منابع پیش پرداخت سنواتی | E16: =SUM(E15:E15) -> 180631824 | F16: =SUM(F15:F15) -> 0
A17: جمع کل پرداختهای غیر قطعی اعتبارات هزینه ای | E17: =+E16+E14+E6 -> 183131824 | F17: =+F16+F14+F6 -> 97713101
A18: دکتر سعيد رضا زارع | B18: توسعه علوم مهندسي | C18: 1389 | D18: اختصاصي-مصوب ملي | E18: 279415035
A19: تاكسيراني-دكترسعيدصمدي | B19: توسعه فنافرینی | C19: 1396 | D19: اختصاصی مصوب | E19: 70000000
A20: تاكسيراني-دكترسعيدصمدي | B20: پژوهش و راهبری فناوری | C20: 1396 | D20: اختصاصی مصوب | E20: 60687500
A21: عليرضا رامندي | B21: توسعه فنافرینی | C21: 1397 | D21: هزينه اي-مصوب ملي | E21: 10000000
A22: اعتبارات اختصاصی پیش پرداخت سنواتی | E22: =SUM(E18:E21) -> 420102535 | F22: =SUM(F18:F21) -> 0
A23: شرکت صنعت فناور سناباد | B23: =[2]سنواتی!B118 -> توسعه كارآفريني | C23: 1389 | D23: =[2]سنواتی!D118 -> اختصاصي-مصوب ملي | F23: =[2]سنواتی!F118 -> 35000000
A24: شرکت مه پخت کار آفرينان توس | B24: =[2]سنواتی!B119 -> توسعه كارآفريني | C24: 1389 | D24: =[2]سنواتی!D119 -> اختصاصي-مصوب ملي | F24: =[2]سنواتی!F119 -> 10000000
A25: داود تفضلی | B25: توسعه علوم مهندسي | C25: 1394 | D25: اختصاصي-مصوب ملي | F25: 20000000
A26: عليرضا نوريان | B26: توسعه علوم مهندسی | C26: 1395 | D26: مصوب ملی | F26: 20000000
A27: تاكسيراني-دكترسعيدصمدي | B27: توسعه فنافرینی | C27: 1396 | D27: اختصاصی مصوب | F27: 59500000
A28: مرتضي دزياني | B28: توسعه فنافرینی | C28: 1396 | D28: اختصاصی مصوب | F28: 951150
A29: كيان تدبير | B29: حمایت از مالکیت فکری | C29: 1396 | D29: اختصاصی مصوب | F29: 33961930
A30: سيد عبدالجواد احمدي | B30: توسعه فنافرینی | C30: 1397 | D30: هزينه اي-مصوب ملي | F30: 29760000
A31: حسين تقوي | B31: توسعه فنافرینی | C31: 1397 | D31: هزينه اي-مصوب ملي | F31: 2480000
A32: ادوات راهداري شهاب | B32: توسعه فنافرینی | C32: 1397 | D32: هزينه اي-مصوب ملي | F32: 71232000
A33: اعتبارات اختصاصی علی الحساب سنواتی | E33: =SUM(E23:E32) -> 0 | F33: =SUM(F23:F32) -> 282885080
A34: جمع کل پرداختهای غیر قطعی اعتبارات اختصاصی | E34: =E22+E33 -> 420102535 | F34: =F22+F33 -> 282885080
A35: عليرضا نوريان | B35: تجهیزات آزمایشگاهی | C35: 1391 | D35: تملک - ابلاغی | F35: 481963
A36: پويند الکترونيک | B36: صکوک | C36: 1395 | D36: صکوک | F36: 100000000
A37: اعتبارات تملک داراییها -علی الحساب سنواتی ابلاغی | E37: =SUBTOTAL(9,E35:E35) -> 0 | F37: =SUBTOTAL(9,F35:F36) -> 100481963
A38: سعيد جسمي | B38: طرح | C38: 1389 | D38: سایر منابع تملک داراییهای سرمایه ای | F38: 7154936
A39: علی الحساب سایر منابع سنواتی تملک داراییهای سرمایه ای | F39: =SUM(F38:F38) -> 7154936
A40: جمع کل پرداختهای غیر قطعی سایر منابع تملک داراییهای سرمایه ای | E40: =+E37 -> 0 | F40: =F39+F37 -> 107636899
...

Sheet مانده پرداختهای غیر قطعی جا
A1: فهرست مانده پرداختهای غیرقطعی سال جاری اعتبارات (هزینه ای، اختصاصی، تملک دارائیهای سرمایه ای و سایرمنابع) سال مالی منتهی به 29 اسفندماه 1398
A2: پارک علم و فناوری خراسان
A3: نام گیرنده | B3: موضوع پرداخت | C3: سال پرداخت | D3: منبع اعتبار | E3: نوع و مبلغ پرداختی
E4: پیش پرداخت | F4: علی الحساب
A5: واحد سير رضوي | B5: تجاری سازی یافته پژوهشی | C5: 1398 | D5: مصوب هزینه ای | F5: 15980000
A6: نوآوران پژوهان آريان | B6: تجاری سازی یافته پژوهشی | C6: 1398 | D6: مصوب هزینه ای | F6: 10000000
A7: ناظمان صدیق رضوان | B7: تجاری سازی یافته پژوهشی | C7: 1398 | D7: مصوب هزینه ای | F7: 70000000
A8: سيد عبدالجواد احمدي | B8: پژوهش و راهبری | C8: 1398 | D8: مصوب هزینه ای | F8: 36720000
A9: مساعده کارکنان | B9: تجاری سازی یافته پژوهشی | C9: 1398 | D9: مصوب هزینه ای | F9: 253259914
A10: اعتبارات هزینه ای علی الحساب سال جاری مصوب | E10: =SUM(E5:E9) -> 0 | F10: =SUM(F5:F9) -> 385959914
A11: الهه مرادي | B11: توسعه فنافرینی | C11: 1398 | D11: مصوب هزینه ای | E11: 10000000
A12: مصطفي آقاحاجي | B12: توسعه فنافرینی | C12: 1398 | D12: مصوب هزینه ای | E12: 10000000
A13: فائزه سهيلي | B13: توسعه فنافرینی | C13: 1398 | D13: مصوب هزینه ای | E13: 10000000
A14: محمد پورعلي | B14: توسعه فنافرینی | C14: 1398 | D14: مصوب هزینه ای | E14: 10000000
A15: فاطمه حبيبي | B15: توسعه فنافرینی | C15: 1398 | D15: مصوب هزینه ای | E15: 10000000
A16: محمد رضا شريفي حصار | B16: توسعه فنافرینی | C16: 1398 | D16: مصوب هزینه ای | E16: 10000000
A17: علي برجسته دلفروز | B17: توسعه فنافرینی | C17: 1398 | D17: مصوب هزینه ای | E17: 12500000
A18: محمد خسروي | B18: توسعه فنافرینی | C18: 1398 | D18: مصوب هزینه ای | E18: 15000000
A19: محمد امين سليماني | B19: توسعه فنافرینی | C19: 1398 | D19: مصوب هزینه ای | E19: 15000000
A20: علي ساقي | B20: توسعه فنافرینی | C20: 1398 | D20: مصوب هزینه ای | E20: 12500000
A21: سيد مصطفي حسيني | B21: توسعه فنافرینی | C21: 1398 | D21: مصوب هزینه ای | E21: 10000000
A22: اسماعيل عابدي | B22: توسعه فنافرینی | C22: 1398 | D22: مصوب هزینه ای | E22: 15000000
... A25: بريد سامانه نوين | B25: پژوهش و راهبری فناوری | C25: 1398 | D25: مصوب هزینه ای | E25: 252000000
A26: اعتبارات هزینه ای پیش پرداخت سال جاری | E26: =SUM(E11:E25) -> 422000000 | F26: =SUM(F11:F25) -> 0
A27: جمع کل پرداختهای غیر قطعی اعتبارات هزینه ای | E27: =E26+E10 -> 422000000 | F27: =F26+F10 -> 385959914
A28: نانو ساختار آویژه | B28: تجاری سازی یافته های پژوهشی | C28: 1398 | D28: اختصاصی مصوب | E28: 477600000
A29: اعتبارات اختصاصی پ پ جاری | E29: =SUM(E28:E28) -> 477600000 | F29: =SUM(F28:F28) -> 0
A30: تاكسيراني-دكترسعيدصمدي | B30: تجاری سازی یافته های پژوهشی | C30: 1398 | D30: اختصاصی مصوب | F30: 60000000
A31: كيان تدبير | B31: تجاری سازی یافته های پژوهشی | C31: 1398 | D31: اختصاصی مصوب | F31: 139408129
A32: اعتبارات اختصاصی علی الحساب جاری | E32: =SUM(E30:E31) -> 0 | F32: =SUM(F30:F31) -> 199408129
A33: جمع کل پرداختهای غیر قطعی اعتبارات اختصاصی | E33: =E32+E29 -> 477600000 | F33: =F32+F29 -> 199408129
A34: جمع کل پرداختهای غیر قطعی سالجاری | E34: =E33+E27 -> 899600000 | F34: =F33+F27 -> 585368043
A35: جمع کل پرداختهای غیر قطعی سنواتی | E35: ='مانده پرداختهای غیر قطعی سن'!E41 -> 603234359 | F35: ='مانده پرداختهای غیر قطعی سن'!F41 -> 488235080
A36: جمع کل پرداختهای غیر قطعی (سالجاری و سنواتی) | E36: =E35+E34 -> 1502834359 | F36: =F35+F34 -> 1073603123

Sheet دارایی ثابت مشهود
A1: پارک علم و فناوری خراسان
A2: یادداشت های توضیحی همراه صورتهای مالی
A3: سال مالی منتهی 29 اسفند ماه 1398
A4: 8-داراييهاي ثابت مشهود
A5: جدول بهاي تمام شده و استهلاك انباشته داراييهاي ثابت مشهود به شرح زير است :
E6: بهاي تمام شده - ريال | J6: استهلاك انباشته - ريال | N6: ارزش دفتري - ريال
B7: شرح اقلام | D7: یادداشت | E7: مانده در ابتدای سال | F7: فروش - اسقاط | G7: دارايي هاي اضافه شده طي سال مالي | H7: مانده در 1398/12/29 | J7: مانده در ابتدای سال | K7: استهلاك سال مالي | L7: استهلاک دارييهاي فروخته شده طي سال مالي | M7: مانده در 1398/12/29 | N7: مانده در 1398/12/29 | O7: مانده در 1397/12/29
A8: زمین | D8: 8-1 | E8: 560247500000 | G8: 0 | H8: =SUM(E8:G8) -> 560247500000 | J8: 0 | K8: 0 | M8: =J8+K8-L8 -> 0 | N8: =H8-M8 -> 560247500000 | O8: =E8-J8 -> 560247500000
A9: ساختمان و مستحدثات | D9: 8-2 | E9: 338859668880 | G9: =678251626+3190358100-3868609726 -> 0 | H9: =SUM(E9:G9) -> 338859668880 | J9: 10852064819 | K9: =5661946862+3333333 -> 5665280195 | M9: =J9+K9+L9 -> 16517345014 | N9: =H9-M9 -> 322342323866 | O9: =E9-J9 -> 328007604061 | Q9: 3868609726
A10: اثاثیه منصوبات | D10: 8-3 | E10: =17221854597+1355901000 -> 18577755597 | F10: -15530000 | G10: =3989907500+275866000-1355901000 -> 2909872500 | H10: =SUM(E10:G10) -> 21472098097 | J10: 4629071271 | K10: 2962877670 | L10: -6957498 | M10: =J10+K10+L10 -> 7584991443 | N10: =H10-M10 -> 13887106654 | O10: =E10-J10 -> 13948684326
A11: ماشین الات وتجهیزات | D11: 8-4 | E11: 5507615500 | G11: 0 | H11: =SUM(E11:G11) -> 5507615500 | J11: 1192251364 | K11: 651001937 | M11: =J11+K11+L11 -> 1843253301 | N11: =H11-M11 -> 3664362199 | O11: =E11-J11 -> 4315364136
A12: وسایط نقلیه | D12: 8-5 | E12: 351750002 | F12: -184100000 | G12: 0 | H12: =SUM(E12:G12) -> 167650002 | J12: 47594029 | K12: 24948333 | L12: =-35797221 -> -35797221 | M12: =J12+K12+L12 -> 36745141 | N12: =H12-M12 -> 130904861 | O12: =E12-J12 -> 304155973
A13: جمع دارایی های ثابت مشهود | E13: =SUM(E8:E12) -> 923544289979 | F13: =SUM(F8:F12) -> -199630000 | G13: =SUM(G8:G12) -> 2909872500 | H13: =SUM(H8:H12) -> 926254532479 | I13: =SUM(I8:I12) -> 0 | J13: =SUM(J8:J12) -> 16720981483 | K13: =SUM(K8:K12) -> 9304108135 | L13: =SUM(L8:L12) -> -42754719 | ... O13: =SUM(O8:O12) -> 906823308496
A15: دارایی در جریان تکمیل | D15: 8-6 | E15: 0 | G15: 30351721935 | H15: =SUM(E15:G15) -> 30351721935 | N15: =H15-M15 -> 30351721935 | O15: =E15-J15 -> 0
A16: جمع کل دارایی ثابت مشهود | B16: جــمــع | E16: =E15+E13 -> 923544289979 | F16: =F15+F13 -> -199630000 | G16: =G15+G13 -> 33261594435 | H16: =H15+H13 -> 956606254414 | I16: =I15+I13 -> 0 | J16: =J15+J13 -> 16720981483 | K16: =K15+K13 -> 9304108135 | L16: =L15+L13 -> -42754719 | ... O16: =O15+O13 -> 906823308496
A18: در سال مورد رسیدگی، دارایی ها به مبلغ 72 میلیارد ریال تحت پوشش بیمه ای قرار گرفته است.

Sheet دارایی نامشهود
A1: پارک علم و فناوری خراسان
A2: یادداشت های توضیحی همراه صورتهای مالی
A3: سال مالی منتهی 29 اسفند ماه 1398
A4: 9-داراييهاي ثابت نامشهود
A5: جدول بهاي تمام شده و استهلاك انباشته داراييهاي ثابت نامشهود به شرح زير است :
E6: بهاي تمام شده - ريال | J6: استهلاك انباشته - ريال | N6: ارزش دفتري - ريال
B7: شرح اقلام | D7: یادداشت | E7: مانده در ابتدای سال | F7: نقل و انتقال بین دارایی ها | G7: داراييهاي اضافه شده طي سال مالي | H7: مانده در 1398/12/29 | J7: مانده در ابتدای سال | K7: استهلاك سال مالي | L7: استهلاک داراييهاي فروخته شده طي سال مالي | M7: مانده در 1398/12/29 | N7: مانده در 1398/12/29 | O7: مانده در 1397/12/29
A8: نرم افزار ها | D8: 9-2 | E8: 1736287500 | F8: 0 | G8: 2953900000 | H8: =SUM(E8:G8) -> 4690187500 | J8: 220416667 | K8: 121540000 | L8: 0 | M8: =J8+K8-L8 -> 341956667 | N8: =H8-M8 -> 4348230833 | O8: =E8-J8 -> 1515870833
A9: حق الامتیاز و فرانشیز | D9: 9-1 | E9: 26828450000 | F9: 0 | G9: 207527951 | H9: =SUM(E9:G9) -> 27035977951 | J9: 0 | K9: 0 | L9: 0 | M9: =J9+K9-L9 -> 0 | N9: =H9-M9 -> 27035977951 | O9: =E9-J9 -> 26828450000
A10: دارایی نامشهود در جریان تکمیل | E10: 0 | F10: 0 | G10: 1002800000 | H10: =SUM(E10:G10) -> 1002800000 | J10: 0 | K10: 0 | L10: 0 | M10: =J10+K10-L10 -> 0 | N10: =H10-M10 -> 1002800000 | O10: =E10-J10 -> 0
A11: جمع کل دارایی ثابت مشهود | B11: جــمــع | E11: =SUM(E8:E10) -> 28564737500 | F11: =SUM(F8:F10) -> 0 | G11: =SUM(G8:G10) -> 4164227951 | H11: =SUM(H8:H10) -> 32728965451 | J11: =SUM(J8:J10) -> 220416667 | K11: =SUM(K8:K10) -> 121540000 | L11: =SUM(L8:L10) -> 0 | M11: =SUM(M8:M10) -> 341956667 | N11: =SUM(N8:N10) -> 32387008784 | O11: =SUM(O8:O10) -> 28344320833

Sheet دارایی ثابت قدیمی
A1: پارک علم و فناوری استان خراسان
A2: یادداشت های توضیحی همراه صورتهای مالی
A3: سال مالی منتهی 29 اسفند ماه 1397
A4: -8 | B4: داراييهاي ثابت مشهود
A5: جدول بهاي تمام شده و استهلاك انباشته داراييهاي ثابت مشهود به شرح زير است :
E6: بهاي تمام شده - ريال | M6: استهلاك انباشته - ريال | U6: ارزش دفتري - ريال
B7: شرح اقلام | E7: مانده در ابتدای سال | F7: تعدیلات | G7: دارييهاي اضافه شده طي سال مالي | I7: نقل و انتقال بین دارایی ها | K7: مانده در 1397/12/29 | M7: مانده در ابتدای سال | O7: استهلاك سال مالي | Q7: استهلاک دارييهاي فروخته شده طي سال مالي | S7: مانده در 97/12/29 | U7: مانده در 1397/12/29 | W7: مانده در 1396/12/29
A8: زمین
A9: اثاثیه منصوبات | E9: 6137272530 | G9: 1398807450 | I9: 0 | K9: =G9+E9+I9 -> 7536079980 | U9: =K9-S9 -> 7536079980 | W9: 6137272530
A10: ماشین الات وتجهیزات | E10: 6280866446 | G10: 3190358100 | K10: =G10+E10+I10 -> 9471224546 | U10: =K10-S10 -> 9471224546 | W10: 6280866446
A11: ساختمان و مستحدثات
A12: تاسیسات
A13: وسایط نقلیه
A14: دارایی در جریان تکمیل | E14: 17140568766 | G14: 678251626 | K14: =G14+E14+I14+F14 -> 17818820392 | M14: 0 | O14: 0 | Q14: 0 | S14: 0 | U14: =K14-S14 -> 17818820392 | W14: 17140568766
A15: علی الحساب سرمایه ای | E15: 0 | K15: =G15+E15+I15+F15 -> 0 | U15: =K15-S15 -> 0 | W15: 0
A16: پیش پرداخت سرمایه ای | G16: 0 | K16: =G16+E16+I16+F16 -> 0 | U16: =K16-S16 -> 0
A17: جمع کل | B17: جــمــع | E17: =SUM(E8:E16) -> 29558707742 | F17: =SUM(F8:F16) -> 0 | G17: =SUM(G8:G16) -> 5267417176 | I17: =SUM(I8:I16) -> 0 | K17: =SUM(K8:K16) -> 34826124918 | M17: =SUM(M8:M16) -> 0 | O17: =SUM(O8:O16) -> 0 | Q17: =SUM(Q8:Q16) -> 0 | S17: =SUM(S8:S16) -> 0 | U17: =SUM(U8:U16) -> 34826124918 | W17: =SUM(W8:W16) -> 29558707742
A19: در سال مورد رسیدگی، دارایی ها به مبلغ 110 میلیارد ریال تحت پوشش بیمه ای قرار گرفته است
B21: دارایی نامشهود به این جدول اضافه شود - نرم افزار ها فقط به این جدول اضافه شود - هزینه استلاک - دارایی نامشهود

Sheet دارایی ثابت (2)
A1: پارک علم و فناوری استان خراسان رضوی
A2: یادداشت های توضیحی همراه صورتهای مالی
A3: سال مالی منتهی 29 اسفند ماه 1397
A4: -8 | B4: داراييهاي ثابت مشهود
A5: جدول بهاي تمام شده و استهلاك انباشته داراييهاي ثابت مشهود به شرح زير است :
D6: بهاي تمام شده - ريال | K6: استهلاك انباشته - ريال | P6: ارزش دفتري - ريال
B7: شرح اقلام | D7: مانده در ابتدای سال | E7: تعدیلات | F7: مانده ابتدای دوره تعدیل شده | G7: دارييهاي اضافه شده طي سال مالي | H7: نقل و انتقال بین دارایی ها | I7: مانده در 1397/12/29 | K7: مانده در ابتدای سال | L7: تعدیلات | M7: استهلاك سال مالي | N7: استهلاک دارييهاي فروخته شده طي سال مالي | O7: مانده در 97/12/29 | P7: مانده در 1397/12/29 | Q7: مانده در 1396/12/29
A8: زمین | D8: 0 | E8: 560247500000 | F8: =E8+D8 -> 560247500000 | I8: =G8+D8+H8+E8 -> 560247500000 | K8: 0 | L8: 0 | O8: =K8+L8+M8-N8 -> 0 | P8: =I8-O8 -> 560247500000 | Q8: 0
A9: ساختمان و مستحدثات | D9: 0 | E9: 338859668880 | F9: =E9+D9 -> 338859668880 | G9: =678251626+3190358100 -> 3868609726 | I9: =G9+D9+H9+E9 -> 342728278606 | K9: 0 | L9: 5190117957 | M9: 5661946862 | O9: =K9+L9+M9-N9 -> 10852064819 | P9: =I9-O9 -> 331876213787 | Q9: 0
A10: اثاثیه منصوبات | D10: 6137272530 | E10: =12597041650-D10+1848771 -> 6461617891 | F10: =E10+D10 -> 12598890421 | G10: =1398807450 -> 1398807450 | I10: =G10+D10+H10+E10 -> 13997697871 | K10: 0 | L10: =1836702446+139248740 -> 1975951186 | M10: 2653120085 | O10: =K10+L10+M10-N10 -> 4629071271 | P10: =I10-O10 -> 9368626600 | Q10: 6137272530
A11: ماشین الات وتجهیزات | D11: 6280866446 | E11: =4663162500+200000000-D11 -> -1417703946 | F11: =E11+D11 -> 4863162500 | I11: =G11+D11+H11+E11 -> 4863162500 | K11: 0 | L11: =522908204+3055556+11952334 -> 537916094 | M11: =651001937+3333333 -> 654335270 | O11: =K11+L11+M11-N11 -> 1192251364 | P11: =I11-O11 -> 3670911136 | Q11: 6280866446
A12: وسایط نقلیه | D12: 0 | E12: 351750002 | F12: =E12+D12 -> 351750002 | I12: =G12+D12+H12+E12 -> 351750002 | K12: 0 | L12: 22762363 | M12: 24831666 | O12: =K12+L12+M12-N12 -> 47594029 | P12: =I12-O12 -> 304155973 | Q12: 0
A13: دارایی در جریان تکمیل | D13: 17140568766 | E13: -17140568766 | F13: =E13+D13 -> 0 | I13: =G13+D13+H13+E13 -> 0 | K13: 0 | M13: 0 | N13: 0 | O13: =K13+L13+M13-N13 -> 0 | P13: =I13-O13 -> 0 | Q13: 17140568766
A14: علی الحساب سرمایه ای | D14: 0 | I14: =G14+D14+H14+E14 -> 0 | P14: =I14-O14 -> 0 | Q14: 0
A15: پیش پرداخت سرمایه ای | G15: 0 | I15: =G15+D15+H15+E15 -> 0 | P15: =I15-O15 -> 0
A16: جمع کل دارایی ثابت مشهود | B16: جــمــع | D16: =SUM(D8:D15) -> 29558707742 | E16: =SUM(E8:E15) -> 887362264061 | F16: =SUM(F8:F15) -> 916920971803 | G16: =SUM(G8:G15) -> 5267417176 | H16: =SUM(H8:H15) -> 0 | I16: =SUM(I8:I15) -> 922188388979 | K16: =SUM(K8:K15) -> 0 | L16: =SUM(L8:L15) -> 7726747600 | M16: =SUM(M8:M15) -> 8994233883 | N16: =SUM(N8:N15) -> 0 | O16: =SUM(O8:O15) -> 16720981483 | P16: =SUM(P8:P15) -> 905467407496 | Q16: =SUM(Q8:Q15) -> 29558707742
F17: 921,629,987,532
A18: -9 | B18: داراييهاي ثابت نا مشهود | F18: =F17-F16 -> 4709015729
D19: بهاي تمام شده - ريال | K19: استهلاك انباشته - ريال | P19: ارزش دفتري - ريال
B20: شرح اقلام | D20: مانده در ابتدای سال | E20: تعدیلات | F20: مانده ابتدای دوره تعدیل شده | G20: دارييهاي اضافه شده طي سال مالي | H20: نقل و انتقال بین دارایی ها | I20: مانده در 1397/12/29 | K20: مانده در ابتدای سال | L20: تعدیلات | M20: استهلاك سال مالي | N20: استهلاک دارييهاي فروخته شده طي سال مالي | O20: مانده در 97/12/29 | P20: مانده در 1397/12/29 | Q20: مانده در 1396/12/29
A21: حق الامتیاز آب | D21: 0 | E21: 19505000000 | F21: =E21+D21 -> 19505000000 | I21: =F21+G21+H21 -> 19505000000 | O21: =K21+L21+M21-N21 -> 0 | P21: =I21-O21 -> 19505000000 | Q21: =D21 -> 0
A22: حق الامتیاز برق | D22: 31854000 | E22: 3260000000 | F22: =E22+D22 -> 3291854000 | G22: 1396476000 | I22: =F22+G22+H22 -> 4688330000 | O22: =K22+L22+M22-N22 -> 0 | P22: =I22-O22 -> 4688330000 | Q22: =D22 -> 31854000
A23: حق الامتیاز گاز | D23: 7120000 | E23: 1830000000 | F23: =E23+D23 -> 1837120000 | I23: =F23+G23+H23 -> 1837120000 | O23: =K23+L23+M23-N23 -> 0 | P23: =I23-O23 -> 1837120000 | Q23: =D23 -> 7120000
A24: خطوط تلفن | D24: 0 | E24: 798000000 | F24: =E24+D24 -> 798000000 | I24: =F24+G24+H24 -> 798000000 | O24: =K24+L24+M24-N24 -> 0 | P24: =I24-O24 -> 798000000 | Q24: =D24 -> 0
A25: نرم افزار ها | D25: 32700000 | E25: 1150000000 | F25: =E25+D25 -> 1182700000 | G25: 553587500 | I25: =F25+G25+H25 -> 1736287500 | L25: 105416667 | M25: 115000000 | O25: =K25+L25+M25-N25 -> 220416667 | P25: =I25-O25 -> 1515870833 | Q25: =D25 -> 32700000
A26: جمع کل دارایی ثابت مشهود | B26: جــمــع | D26: =SUM(D21:D25) -> 71674000 | E26: =SUM(E21:E25) -> 26543000000 | F26: =SUM(F21:F25) -> 26614674000 | G26: =SUM(G21:G25) -> 1950063500 | H26: =SUM(H21:H25) -> 0 | I26: =SUM(I21:I25) -> 28564737500 | K26: =SUM(K21:K25) -> 0 | L26: =SUM(L21:L25) -> 105416667 | M26: =SUM(M21:M25) -> 115000000 | N26: =SUM(N21:N25) -> 0 | O26: =SUM(O21:O25) -> 220416667 | P26: =SUM(P21:P25) -> 28344320833 | Q26: =SUM(Q21:Q25) -> 71674000
A27: در سال مورد رسیدگی، دارایی ها به مبلغ 110 میلیارد ریال تحت پوشش بیمه ای قرار گرفته است
B29: دارایی نامشهود به این جدول اضافه شود - نرم افزار ها فقط به این جدول اضافه شود - هزینه استلاک - دارایی نامشهود | I29: 922183908979
G32: =1398807450+3224156726 -> 4622964176
G33: =3190358100+678251626-3224156726 -> 644453000

Sheet دارایی ثابت (3)
A1: پارک علم و فناوری استان خراسان
A2: یادداشت های توضیحی همراه صورتهای مالی
A3: سال مالی منتهی 29 اسفند ماه 1397
A4: 8-داراييهاي ثابت مشهود
A5: جدول بهاي تمام شده و استهلاك انباشته داراييهاي ثابت مشهود به شرح زير است :
E6: بهاي تمام شده - ريال | K6: استهلاك انباشته - ريال | P6: ارزش دفتري - ريال
B7: شرح اقلام | D7: یادداشت | E7: مانده در ابتدای سال | F7: نقل و انتقال بین دارایی ها | G7: شناسایی اولیه دارایی | H7: دارايي هاي اضافه شده طي سال مالي | I7: مانده در 1397/12/29 | K7: مانده در ابتدای سال | L7: استهلاک دارائیهای شناسائی شده | M7: استهلاك سال مالي | N7: استهلاک دارييهاي فروخته شده طي سال مالي | O7: مانده در 97/12/29 | P7: مانده در 1397/12/29 | Q7: مانده در 1396/12/29
A8: زمین | D8: 8-1 | E8: 0 | G8: 560247500000 | H8: 0 | I8: =SUM(E8:H8) -> 560247500000 | K8: 0 | L8: 0 | M8: 0 | O8: =K8+L8+M8-N8 -> 0 | P8: =I8-O8 -> 560247500000 | Q8: 0
A9: ساختمان و مستحدثات | D9: 8-2 | E9: 0 | F9: =1417703946+17140568766 -> 18558272712 | G9: =338859668880-F9 -> 320301396168 | H9: =678251626+3190358100 -> 3868609726 | I9: =SUM(E9:H9) -> 342728278606 | K9: 0 | L9: 5190117957 | M9: 5661946862 | O9: =K9+L9+M9-N9 -> 10852064819 | P9: =I9-O9 -> 331876213787 | Q9: 0
A10: اثاثیه منصوبات | D10: 8-3 | E10: 6137272530 | F10: -644453000 | G10: =12597041650-E10+1848771 -> 6461617891 | H10: =1398807450 -> 1398807450 | I10: =SUM(E10:H10) -> 13353244871 | K10: 0 | L10: =1836702446+139248740 -> 1975951186 | M10: 2653120085 | O10: =K10+L10+M10-N10 -> 4629071271 | P10: =I10-O10 -> 8724173600 | Q10: 6137272530
A11: ماشین الات وتجهیزات | D11: 8-4 | E11: 6280866446 | F11: =-1417703946+644453000 -> -773250946 | G11: 0 | H11: 0 | I11: =SUM(E11:H11) -> 5507615500 | K11: 0 | L11: =522908204+3055556+11952334 -> 537916094 | M11: =651001937+3333333 -> 654335270 | O11: =K11+L11+M11-N11 -> 1192251364 | P11: =I11-O11 -> 4315364136 | Q11: 6280866446
A12: وسایط نقلیه | D12: 8-5 | E12: 0 | F12: 0 | G12: 351750002 | H12: 0 | I12: =SUM(E12:H12) -> 351750002 | K12: 0 | L12: 22762363 | M12: 24831666 | O12: =K12+L12+M12-N12 -> 47594029 | P12: =I12-O12 -> 304155973 | Q12: 0
A13: دارایی در جریان تکمیل | D13: 8-6 | E13: 17140568766 | F13: =-17140568766 -> -17140568766 | G13: 0 | H13: 0 | I13: 0 | K13: 0 | M13: 0 | N13: 0 | O13: =K13+L13+M13-N13 -> 0 | P13: =I13-O13 -> 0 | Q13: 17140568766
A14: جمع کل دارایی ثابت مشهود | B14: جــمــع | E14: =SUM(E8:E13) -> 29558707742 | F14: =SUM(F8:F13) -> 0 | G14: =SUM(G8:G13) -> 887362264061 | H14: =SUM(H8:H13) -> 5267417176 | I14: =SUM(I8:I13) -> 922188388979 | K14: =SUM(K8:K13) -> 0 | L14: =SUM(L8:L13) -> 7726747600 | M14: =SUM(M8:M13) -> 8994233883 | N14: =SUM(N8:N13) -> 0 | O14: =SUM(O8:O13) -> 16720981483 | P14: =SUM(P8:P13) -> 905467407496 | Q14: =SUM(Q8:Q13) -> 29558707742
A16: -9 | B16: داراييهاي ثابت نامشهود
E17: بهاي تمام شده - ريال | K17: استهلاك انباشته - ريال | P17: ارزش دفتري - ريال
B18: شرح اقلام | D18: یادداشت | E18: مانده در ابتدای سال | F18: نقل و انتقال بین دارایی ها | G18: شناسایی اولیه دارایی | H18: دارييهاي اضافه شده طي سال مالي | I18: مانده در 1397/12/29 | K18: مانده در ابتدای سال | L18: استهلاک دارائیهای شناسائی شده | M18: استهلاك سال مالي | N18: استهلاک دارييهاي فروخته شده طي سال مالي | O18: مانده در 97/12/29 | P18: مانده در 1397/12/29 | Q18: مانده در 1396/12/29
A19: نرم افزار ها | E19: 32700000 | F19: 0 | G19: 1150000000 | H19: 553587500 | I19: =SUM(E19:H19) -> 1736287500 | L19: 105416667 | M19: 115000000 | O19: =K19+L19+M19-N19 -> 220416667 | P19: =I19-O19 -> 1515870833 | Q19: =E19 -> 32700000
A20: جمع کل دارایی ثابت مشهود | B20: جــمــع | E20: =SUM(E19:E19) -> 32700000 | F20: =SUM(F19:F19) -> 0 | G20: =SUM(G19:G19) -> 1150000000 | H20: =SUM(H19:H19) -> 553587500 | I20: =SUM(I19:I19) -> 1736287500 | K20: =SUM(K19:K19) -> 0 | L20: =SUM(L19:L19) -> 105416667 | M20: =SUM(M19:M19) -> 115000000 | N20: =SUM(N19:N19) -> 0 | O20: =SUM(O19:O19) -> 220416667 | P20: =SUM(P19:P19) -> 1515870833 | Q20: =SUM(Q19:Q19) -> 32700000
A26: حق الامتیاز آب | E26: 0 | G26: 19505000000 | I26: =SUM(E26:H26) -> 19505000000 | O26: =K26+L26+M26-N26 -> 0 | P26: =I26-O26 -> 19505000000 | Q26: =E26 -> 0
A27: حق الامتیاز برق | E27: 31854000 | G27: 3260000000 | H27: 1396476000 | I27: =SUM(E27:H27) -> 4688330000 | O27: =K27+L27+M27-N27 -> 0 | P27: =I27-O27 -> 4688330000 | Q27: =E27 -> 31854000
A28: حق الامتیاز گاز | E28: 7120000 | G28: 1830000000 | I28: =SUM(E28:H28) -> 1837120000 | O28: =K28+L28+M28-N28 -> 0 | P28: =I28-O28 -> 1837120000 | Q28: =E28 -> 7120000
A29: خطوط تلفن | E29: 0 | G29: 798000000 | I29: =SUM(E29:H29) -> 798000000 | O29: =K29+L29+M29-N29 -> 0 | P29: =I29-O29 -> 798000000 | Q29: =E29 -> 0

Sheet درآمد دولت
A2: 26-1-مقایسه پیش بینی و وصولی درآمد اختصاصی سال مالی منتهی به 1398/12/29 بشرح ذيل مي باشد
A4: شرح درآمد | C4: بودجه | D4: ارسالی به خزانه | E4: درصد وصولي نسبت به پيش بيني
A5: درآمدهای اختصاصی | C5: 56206000000 | D5: =C21 -> 56206000000 | E5: =D5/C5 -> 1
A8: 26-2-مقایسه وصولی درآمد اختصاصی سالهاي 1397 و 1398 بشرح ذيل مي باشد
A10: ردیف | B10: شرح درآمد | C10: وصولی | D10: وصولی | E10: تفاوت کسر یا اضافه درآمد وصولی | G10: درصد كسر يا اضافه نسبت به وصولي94
C11: 1398 | D11: 1397
A12: 1 | B12: درامد حاصل از بازپرداخت تسهیلات | C12: 272000000 | D12: 61000000 | E12: =C12-D12 -> 211000000 | G12: -0.77314805
A13: 2 | B13: درامد حاصل از بازپرداخت حمایت های مالی دریافتی از صندوق پژوهش و فناوری | C13: 0 | D13: 6046497710 | E13: =C13-D13 -> -6046497710
A14: 3 | B14: مشارکت طرحهای تحقیقاتی وبالاسری قراردادی | C14: 24592875009 | D14: 5337894471 | E14: =C14-D14 -> 19254980538 | G14: 118.20644
A15: 4 | B15: مجتمع آزمایشگاهی و پایلوت سرامیک | C15: 2161760327 | D15: 10441957532 | E15: =C15-D15 -> -8280197205 | G15: 0.48171993
A16: 5 | B16: خدمات آموزشی و کارشناسی | C16: 547316000 | D16: 130551000 | E16: =C16-D16 -> 416765000 | G16: 0.12901849
A17: 6 | B17: خدمات مالکیت فکری | C17: 569000000 | D17: 142360000 | E17: =C17-D17 -> 426640000 | G17: 0.25
A18: 7 | B18: درآمد حاصل از اجاره استقرار | C18: 16075316677 | D18: 11569922155 | E18: =C18-D18 -> 4505394522 | G18: 0.66161649
A19: 8 | B19: ارائه خدمات پشتیبانی | C19: 10168214249 | D19: 8885968253 | E19: =C19-D19 -> 1282245996 | G19: 0.67672675
A20: 9 | B20: سود سهام و سپرده | C20: 1819517738 | D20: 2500848879 | E20: =C20-D20 -> -681331141 | G20: -0.1593145
A21: جمع کل | C21: =SUM(C12:C20) -> 56206000000 | D21: =SUM(D12:D20) -> 45117000000 | E21: =SUM(E12:E20) -> 11089000000 | G21: 1.043873

Sheet ن6
G27: 29
A29: درآمد اختصاصی
A31: درآمد اختصاصی پیش بینی
A32: ='درآمد دولت'!C5/1000000 -> 56206
A35: درآمد اختصاصی وصولی
A36: ='درآمد دولت'!D5/1000000 -> 56206

Sheet  مصوب
A1: صورتحساب عملکرد اعتبارات مصوب بودجه (هزینه ای ، تملک داراییهای سرمایه ای ، اختصاصی ) سال 1398
A2: عنوان دستگاه : پارك علم و فناوري خراسان
A3: شماره | B3: عنوان | C3: اعتبارات | G3: دریافتی ازخزانه | I3: نقل و انتقال هیات امنا | J3: جمع | K3: مصرفی | Q3: جمع کل مصرفی | R3: مانده مصرف نشده در پایان سال
A4: برنامه - طرح | C4: ابلاغ قانون بودجه | D4: اصلاحیه | E4: اعتبارمصوب | F4: تخصیص یافته | K4: هزینه | L4: حمایت مالی از واحد های فناور | M4: کمک به صندوق پژوهش بابت حمایت مالی به واحد های فناور | N4: ودایع | O4: پيش پرداخت | P4: علی الحساب | R4: وجه نقد | S4: اسناد خزانه
G5: وجه نقد | H5: استاد خزانه اسلامی | N5: سپرده
A6: جمع عملکرد اعتبارات مصوب هزینه ای | C6: =SUM(C7:C9) -> 145500000000 | D6: =SUM(D7:D9) -> 0 | E6: =SUM(E7:E9) -> 145500000000 | F6: =SUM(F7:F9) -> 116221000000 | G6: =SUM(G7:G9) -> 116221000000 | H6: =SUM(H7:H9) -> 0 | I6: =SUM(I7:I9) -> 0 | J6: =SUM(J7:J9) -> 116221000000 | ... S6: =SUM(S7:S9) -> -0.00014877319
A7: 1804014000 | B7: برنامه پژوهش وراهبري علم وفناوری | C7: 41046000000 | D7: 0 | E7: =C7+D7 -> 41046000000 | F7: 3.2786304e+10 | G7: =F7 -> 3.2786304e+10 | H7: 0 | I7: 0 | J7: =G7+H7+I7 -> 3.2786304e+10 | K7: 31996313617 | L7: 0 | M7: 0 | N7: 367990000 | O7: 422000000 | P7: 0 | Q7: =SUM(K7:P7) -> 32786303617 | R7: =J7-Q7 -> -0.36457825 | S7: -4.9591064e-05
A8: 1805005000 | B8: برنامه تجاري سازي يافته هاي پژوهشي | C8: 49470000000 | D8: 0 | E8: =C8+D8 -> 49470000000 | F8: =39515140084.66-249 -> 3.951514e+10 | G8: =F8 -> 3.951514e+10 | H8: 0 | I8: 0 | J8: =G8+H8+I8 -> 3.951514e+10 | K8: 4115998097 | L8: 0 | M8: 0 | N8: 0 | O8: 0 | P8: 0 | Q8: =SUM(K8:P8) -> 4115998097 | R8: =J8-Q8 -> 3.5399142e+10 | S8: -4.9591064e-05
A9: 1805012000 | B9: برنامه توسعه فن آفريني | C9: 54984000000 | D9: 0 | E9: =C9+D9 -> 54984000000 | F9: 4.3919557e+10 | G9: =F9 -> 4.3919557e+10 | H9: 0 | I9: 0 | J9: =G9+H9+I9 -> 4.3919557e+10 | K9: =31953542370+217991711+54750489+140416117+24866002 -> 32391566689 | L9: =11966014178-217991711-(54750489+140416117+24866002) -> 11527989859 | M9: 0 | N9: 0 | O9: 0 | P9: 0 | Q9: =SUM(K9:P9) -> 43919556548 | R9: =J9-Q9 -> -0.29542542 | S9: -4.9591064e-05
A10: جمع عملکرد اعتبارات مصوب اختصاصی | C10: =SUM(C11:C13) -> 38800000000 | D10: =SUM(D11:D13) -> 17406000000 | E10: =SUM(E11:E13) -> 56206000000 | F10: =SUM(F11:F13) -> 54519820000 | G10: =SUM(G11:G13) -> 54519819997 | H10: =SUM(H11:H13) -> 0 | I10: =SUM(I11:I13) -> -8300000000 | J10: =SUM(J11:J13) -> 46219819997 | ... S10: =SUM(S11:S13) -> 0
A11: 1804014000 | B11: برنامه پژوهش وراهبري علم وفناوری | C11: 11640000000 | D11: =16206000000+(40000000000-38800000000) -> 17406000000 | E11: =C11+D11 -> 29046000000 | F11: =54519820000-F12-F13 -> 27359820000 | G11: =F11-3 -> 27359819997 | H11: 0 | I11: -8300000000 | J11: =G11+H11+I11 -> 19059819997 | K11: =212500000+321804000+31138642330-K12-K13 -> 4691838154 | L11: 0 | M11: 0 | N11: 74000000 | O11: 477600000 | P11: 0 | Q11: =SUM(K11:P11) -> 5243438154 | R11: =J11-Q11 -> 13816381843
A12: 1805005000 | B12: برنامه تجاري سازي يافته هاي پژوهشي | C12: 13580000000 | D12: 0 | E12: =C12+D12 -> 13580000000 | F12: 13580000000 | G12: =F12 -> 13580000000 | H12: 0 | J12: =G12+H12+I12 -> 13580000000 | K12: 13580000000 | L12: 0 | M12: 0 | N12: 0 | O12: 0 | P12: 0 | Q12: =SUM(K12:P12) -> 13580000000 | R12: =J12-Q12 -> 0 | S12: 0
A13: 1805012000 | B13: برنامه توسعه فن آفريني | C13: 13580000000 | D13: 0 | E13: =C13+D13 -> 13580000000 | F13: 13580000000 | G13: =F13 -> 13580000000 | H13: 0 | J13: =G13+H13+I13 -> 13580000000 | K13: 13401108176 | L13: 178891824 | M13: 0 | N13: 0 | O13: 0 | P13: 0 | Q13: =SUM(K13:P13) -> 13580000000 | R13: =J13-Q13 -> 0 | S13: 0
A14: جمع عملکرد اعتبارات مصوب تملک داراییهای سرمایه ای | C14: =SUM(C15:C19) -> 19590000000 | D14: =SUM(D15:D19) -> 0 | E14: =SUM(E15:E19) -> 19590000000 | F14: =SUM(F15:F19) -> 8940000000 | G14: =SUM(G15:G19) -> 5116000000 | H14: =SUM(H15:H19) -> 3824000000 | I14: =SUM(I15:I19) -> 8300000000 | J14: =SUM(J15:J19) -> 17240000000 | ... S14: =SUM(S15:S19) -> 2850000000
A15: 1804014009 | B15: تعمیر و تجهیز | C15: 6090000000 | D15: 0 | E15: =C15+D15 -> 6090000000 | F15: 6090000000 | G15: 5116000000 | H15: 974000000 | J15: =G15+H15+I15 -> 6090000000 | K15: 6090000000 | L15: 0 | M15: 0 | N15: 0 | O15: 0 | P15: 0 | Q15: =SUM(K15:P15) -> 6090000000 | R15: =J15-Q15 -> 0 | S15: 0
A16: - | B16: تملک دارایی های مصوبه هیات امنا | C16: 0 | D16: 0 | E16: =C16+D16 -> 0 | F16: 0 | G16: =F16 -> 0 | H16: 0 | I16: 8300000000 | J16: =G16+H16+I16 -> 8300000000 | K16: 8300000000 | Q16: =SUM(K16:P16) -> 8300000000 | R16: =J16-Q16 -> 0 | S16: 0
A17: 1804014009 | B17: متوازن جزء14 ردیف550000 - پارک | C17: 10000000000 | D17: 0 | E17: =C17+D17 -> 10000000000 | F17: 2500000000 | G17: 0 | H17: =F17 -> 2500000000 | J17: =G17+H17+I17 -> 2500000000 | K17: 0 | L17: 0 | M17: 0 | N17: 0 | O17: 0 | P17: 0 | Q17: =SUM(K17:P17) -> 0 | R17: 0 | S17: =J17-Q17 -> 2500000000
A18: 1804014009 | B18: متوازن جزء14 ردیف550000 - گناباد | C18: 1500000000 | D18: 0 | E18: =C18+D18 -> 1500000000 | F18: 150000000 | G18: 0 | H18: =F18 -> 150000000 | J18: =G18+H18+I18 -> 150000000 | K18: 0 | L18: 0 | M18: 0 | N18: 0 | O18: 0 | P18: 0 | Q18: =SUM(K18:P18) -> 0 | R18: 0 | S18: =J18-Q18 -> 150000000
A19: 1804014009 | B19: متوازن جزء14 ردیف550000 - نیشابور | C19: 2000000000 | D19: 0 | E19: =C19+D19 -> 2000000000 | F19: 200000000 | G19: 0 | H19: =F19 -> 200000000 | J19: =G19+H19+I19 -> 200000000 | K19: 0 | L19: 0 | M19: 0 | N19: 0 | O19: 0 | P19: 0 | Q19: =SUM(K19:P19) -> 0 | R19: 0 | S19: =J19-Q19 -> 200000000
A20: جمع كل مصوب | C20: =C6+C10+C14 -> 203890000000 | D20: =D6+D10+D14 -> 17406000000 | E20: =E6+E10+E14 -> 221296000000 | F20: =F6+F10+F14 -> 179680820000 | G20: =G6+G10+G14 -> 175856819997 | H20: =H6+H10+H14 -> 3824000000 | I20: =I6+I10+I14 -> 0 | J20: =J6+J10+J14 -> 179680819997 | ... S20: =S6+S10+S14 -> 2.85e+09
E22: =E20-F20 -> 41615180000
K23: =K20+'وجوه مصرف نشده'!I28+ابلاغي!J19+'سايرمنابع جاری'!K18 -> 173788651340
K24: ='منابع ومصارف'!G58-'منابع ومصارف'!G47 -> 172581241340 | R24: =R20+'وجوه مصرف نشده'!S28+ابلاغي!K19+'سايرمنابع جاری'!L18 -> 9.9145021e+10
K25: =K24-K23 -> -1207410000 | R25: =يادداشتها!F7+يادداشتها!F8+يادداشتها!F9 -> 99145021477
R26: =R25-R24 -> -0.040008545

Sheet ن2
A33: 35
A36: اعتبارات هزینه ای | B36: =' مصوب'!C6/1000000 -> 145500
A37: اعتبارات سرمایه ای: | B37: =' مصوب'!E14/1000000 -> 19590
A38: اعتبارات اختصاصی: | B38: =' مصوب'!E10/1000000 -> 56206
B41: اعتبارات هزینه ای : 145.500 میلیون ریال
B42: اعتبارات سرمایه ای : 19.590 میلیون ریال
B43: اعتبارات اختصاصی : 56.206 میلیون ریال

Sheet ن1
F31: 36
A38: مصوب
B39: =ن2!$B$36 -> 145500 | E39: اعتبارات جاری
B40: =ن2!$B$37 -> 19590 | E40: اعتبارات سرمایه ای
B41: =ن2!$B$38 -> 56206 | E41: اعتبارات اختصاصی
A43: تخصیص | B43: =' مصوب'!F6/1000000 -> 116221
B44: =' مصوب'!J14/1000000 -> 17240
B45: =' مصوب'!F10/1000000 -> 54519.82
A47: دریافتی از خزانه | B47: =B43 -> 116221
B48: =' مصوب'!J14/1000000 -> 17240
B49: =B45 -> 54519.82

Sheet ن3
E28: 37
A32: دریافتی از خزانه
A33: =ن1!$B$47 -> 116221 | D33: اعتبارات جاری
A34: =ن1!$B$48 -> 17240 | D34: اعتبارات سرمایه ای
A35: =ن1!$B$49 -> 54519.82 | D35: اعتبارات اختصاصی
A36: هزینه
A37: =' مصوب'!K6/1000000 -> 68503.878 | D37: اعتبارات جاری
A38: =' مصوب'!K14/1000000 -> 14390 | D38: اعتبارات سرمایه ای
A39: =' مصوب'!K10/1000000 -> 31672.946 | D39: اعتبارات اختصاصی
A40: پیش پرداخت و علی الحساب
A41: =((' مصوب'!N6+' مصوب'!O6+' مصوب'!P6)/1000000)+1 -> 790.99 | D41: اعتبارات جاری
A42: =(' مصوب'!N14+' مصوب'!O14+' مصوب'!P14)/1000000 -> 0 | D42: اعتبارات سرمایه ای
A43: =(' مصوب'!N10+' مصوب'!O10+' مصوب'!P10)/1000000 -> 551.6 | D43: اعتبارات اختصاصی
A44: حمایت مالی مستقیم از واحد های فناور
A45: 11707 | D45: اعتبارات جاری
A46: =(' مصوب'!L14+' مصوب'!M14)/1000000 -> 0 | D46: اعتبارات سرمایه ای
A47: =(' مصوب'!L10+' مصوب'!M10)/1000000 -> 178.89182 | D47: اعتبارات اختصاصی
A48: مانده وجوه مصرف نشده پایان سال
A49: =' مصوب'!R6/1000000 -> 35399.142 | D49: اعتبارات جاری
A50: =(' مصوب'!R14+' مصوب'!S14)/1000000 -> 2850 | D50: اعتبارات سرمایه ای
A51: =(' مصوب'!R10+' مصوب'!S10)/1000000 -> 13816.382 | D51: اعتبارات اختصاصی

Sheet وجوه مصرف نشده
A2: صورتحساب وضعیت وجوه مصرف نشده سنوات قبل اعتبارات (هزینه ای ،اختصاصی، تملک داراییهای سرمایه ای ) سال 1398
A3: عنوان دستگاه : پارك علم و فناوري خراسان
A4: شماره | B4: عنوان | C4: انتقال مانده ازسال قبل | E4: تعدیل | F4: نقل و انتقال بر اساس مصوبات هیات امنا | G4: واریز نقدی | H4: جمع کل موجودی | I4: مصرفی | M4: جمع کل | N4: بدهی به حساب های مستقل | P4: طلب از حساب های مستقل | R4: تنخواه | S4: مانده مصرف نشده پایان سال
A5: برنامه - طرح | C5: وجه نقد | D5: اسناد خزانه | G5: پیش پرداخت و علی الحساب | I5: هزینه | J5: سرمایه گذاری | K5: پیش پرداخت | L5: علی الحساب | M5: مصرفی | N5: طی سال | O5: مانده پایان دوره | P5: طی سال | Q5: مانده پایان دوره | S5: وجه نقد | T5: اسناد خزانه
A7: جمع عملکرد مانده مصرف نشده اعتبارات هزینه ای | C7: =SUM(C8:C8) -> 8951991964 | D7: =SUM(D8:D8) -> 0 | E7: =SUM(E8:E8) -> 0 | F7: =SUM(F8:F8) -> 0 | G7: =SUM(G8:G8) -> 464760000 | H7: =SUM(H8:H8) -> 9416751964 | I7: =SUM(I8:I8) -> 9416751964 | J7: =SUM(J8:J8) -> 0 | ... T7: =SUM(T8:T8) -> 0
